<sdf version='1.6'>
  <model name='lobot'>
    <link name='base_link'>
      <pose frame=''>0 0 0.25 0 -0 0</pose>
      <inertial>
        <pose frame=''>-0.012076 -0.004415 0.021424 0 -0 0</pose>
        <mass>0.083321</mass>
        <inertia>
          <ixx>0.0341884</ixx>
          <ixy>8.97553e-06</ixy>
          <ixz>0.00238272</ixz>
          <iyy>0.0335204</iyy>
          <iyz>0.000494612</iyz>
          <izz>0.0451606</izz>
        </inertia>
      </inertial>
      <collision name='base_link_collision'>
        <pose frame=''>0 0 0 0 -0 0</pose>
        <geometry>
          <box>
            <size>0.043 0.118 0.095</size>
          </box>
        </geometry>
      </collision>
      <collision name='base_link_fixed_joint_lump__IMU_link_collision_1'>
        <pose frame=''>0 0 0 0 -0 0</pose>
        <geometry>
          <box>
            <size>0.001 0.001 0.001</size>
          </box>
        </geometry>
        <surface>
          <contact>
            <ode/>
          </contact>
          <friction>
            <ode/>
          </friction>
        </surface>
      </collision>
      <visual name='base_link_visual'>
        <pose frame=''>0 0 0 0 -0 0</pose>
        <geometry>
          <box>
            <size>0.043 0.118 0.095</size>
          </box>
        </geometry>
      </visual>
      <visual name='base_link_fixed_joint_lump__IMU_link_visual_1'>
        <pose frame=''>0 0 0 0 -0 0</pose>
        <geometry>
          <box>
            <size>0.001 0.001 0.001</size>
          </box>
        </geometry>
        <material>
          <script>
            <uri>__default__</uri>
            <name>__default__</name>
          </script>
        </material>
      </visual>
      <gravity>1</gravity>
      <velocity_decay/>
      <sensor name='IMU_lobot' type='imu'>
        <always_on>1</always_on>
        <update_rate>10</update_rate>
        <plugin name='lobot_IMU_controller' filename='libgazebo_ros_imu_sensor.so'/>
        <pose frame=''>0 0 0 0 -0 0</pose>
      </sensor>
    </link>
    <joint name='world_joint' type='fixed'>
      <child>base_link</child>
      <parent>world</parent>
    </joint>
    <link name='arm_left_1_link'>
      <pose frame=''>0 0.059 0.2805 0 -0 0</pose>
      <inertial>
        <pose frame=''>0 0 0 0 -0 0</pose>
        <mass>0.05901</mass>
        <inertia>
          <ixx>0.00132188</ixx>
          <ixy>1.514e-08</ixy>
          <ixz>0.000400223</ixz>
          <iyy>0.00185286</iyy>
          <iyz>5.0713e-07</iyz>
          <izz>0.000842313</izz>
        </inertia>
      </inertial>
      <visual name='arm_left_1_link_visual'>
        <pose frame=''>0 0 0 1.5708 -0 0</pose>
        <geometry>
          <cylinder>
            <length>0.02</length>
            <radius>0.01</radius>
          </cylinder>
        </geometry>
      </visual>
    </link>
    <joint name='arm_left_1_joint' type='revolute'>
      <child>arm_left_1_link</child>
      <parent>base_link</parent>
      <axis>
        <xyz>0 1 0</xyz>
        <limit>
          <lower>-1.57</lower>
          <upper>1.57</upper>
          <effort>50</effort>
          <velocity>4</velocity>
        </limit>
        <dynamics>
          <spring_reference>0</spring_reference>
          <spring_stiffness>0</spring_stiffness>
        </dynamics>
        <use_parent_model_frame>1</use_parent_model_frame>
      </axis>
    </joint>
    <link name='arm_left_2_link'>
      <pose frame=''>0 0.08803 0.2805 0 -0 0</pose>
      <inertial>
        <pose frame=''>0 0 0 0 -0 0</pose>
        <mass>0.05901</mass>
        <inertia>
          <ixx>0.00132188</ixx>
          <ixy>1.514e-08</ixy>
          <ixz>0.000400223</ixz>
          <iyy>0.00185286</iyy>
          <iyz>5.0713e-07</iyz>
          <izz>0.000842313</izz>
        </inertia>
      </inertial>
      <visual name='arm_left_2_link_visual'>
        <pose frame=''>0 0 0 3.14159 1.57079 3.14159</pose>
        <geometry>
          <cylinder>
            <length>0.02</length>
            <radius>0.01</radius>
          </cylinder>
        </geometry>
      </visual>
    </link>
    <joint name='arm_left_2_joint' type='revolute'>
      <child>arm_left_2_link</child>
      <parent>arm_left_1_link</parent>
      <axis>
        <xyz>1 0 0</xyz>
        <limit>
          <lower>-1.5708</lower>
          <upper>1.5708</upper>
          <effort>50</effort>
          <velocity>4</velocity>
        </limit>
        <dynamics>
          <spring_reference>0</spring_reference>
          <spring_stiffness>0</spring_stiffness>
        </dynamics>
        <use_parent_model_frame>1</use_parent_model_frame>
      </axis>
    </joint>
    <link name='arm_left_3_link'>
      <pose frame=''>0 0.14659 0.2805 0 -0 0</pose>
      <inertial>
        <pose frame=''>0 0.0225 0 0 -0 0</pose>
        <mass>0.11802</mass>
        <inertia>
          <ixx>0.0027035</ixx>
          <ixy>3.028e-08</ixy>
          <ixz>0.000800445</ixz>
          <iyy>0.00370572</iyy>
          <iyz>1.01426e-06</iyz>
          <izz>0.00174437</izz>
        </inertia>
      </inertial>
      <collision name='arm_left_3_link_fixed_joint_lump__gripper_left_link_collision'>
        <pose frame=''>0 0.045 0 0 -0 0</pose>
        <geometry>
          <box>
            <size>0.04 0.09 0.02</size>
          </box>
        </geometry>
      </collision>
      <visual name='arm_left_3_link_visual'>
        <pose frame=''>0 0 0 3.14159 1.57079 3.14159</pose>
        <geometry>
          <cylinder>
            <length>0.02</length>
            <radius>0.01</radius>
          </cylinder>
        </geometry>
      </visual>
      <visual name='arm_left_3_link_fixed_joint_lump__gripper_left_link_visual_1'>
        <pose frame=''>0 0.045 0 0 -0 0</pose>
        <geometry>
          <box>
            <size>0.04 0.09 0.02</size>
          </box>
        </geometry>
      </visual>
    </link>
    <joint name='arm_left_3_joint' type='revolute'>
      <child>arm_left_3_link</child>
      <parent>arm_left_2_link</parent>
      <axis>
        <xyz>1 0 0</xyz>
        <limit>
          <lower>-1.5708</lower>
          <upper>1.5708</upper>
          <effort>50</effort>
          <velocity>4</velocity>
        </limit>
        <dynamics>
          <spring_reference>0</spring_reference>
          <spring_stiffness>0</spring_stiffness>
        </dynamics>
        <use_parent_model_frame>1</use_parent_model_frame>
      </axis>
    </joint>
    <link name='arm_right_1_link'>
      <pose frame=''>0 -0.059 0.2805 0 -0 0</pose>
      <inertial>
        <pose frame=''>0 0 0 0 -0 0</pose>
        <mass>0.05901</mass>
        <inertia>
          <ixx>0.00132188</ixx>
          <ixy>1.514e-08</ixy>
          <ixz>0.000400223</ixz>
          <iyy>0.00185286</iyy>
          <iyz>5.0713e-07</iyz>
          <izz>0.000842313</izz>
        </inertia>
      </inertial>
      <visual name='arm_right_1_link_visual'>
        <pose frame=''>0 0 0 1.5708 -0 0</pose>
        <geometry>
          <cylinder>
            <length>0.02</length>
            <radius>0.01</radius>
          </cylinder>
        </geometry>
      </visual>
    </link>
    <joint name='arm_right_1_joint' type='revolute'>
      <child>arm_right_1_link</child>
      <parent>base_link</parent>
      <axis>
        <xyz>0 1 0</xyz>
        <limit>
          <lower>-1.57</lower>
          <upper>1.57</upper>
          <effort>50</effort>
          <velocity>4</velocity>
        </limit>
        <dynamics>
          <spring_reference>0</spring_reference>
          <spring_stiffness>0</spring_stiffness>
        </dynamics>
        <use_parent_model_frame>1</use_parent_model_frame>
      </axis>
    </joint>
    <link name='arm_right_2_link'>
      <pose frame=''>0 -0.08803 0.2805 0 -0 0</pose>
      <inertial>
        <pose frame=''>0 0 0 0 -0 0</pose>
        <mass>0.05901</mass>
        <inertia>
          <ixx>0.00132188</ixx>
          <ixy>1.514e-08</ixy>
          <ixz>0.000400223</ixz>
          <iyy>0.00185286</iyy>
          <iyz>5.0713e-07</iyz>
          <izz>0.000842313</izz>
        </inertia>
      </inertial>
      <visual name='arm_right_2_link_visual'>
        <pose frame=''>0 0 0 3.14159 1.57079 3.14159</pose>
        <geometry>
          <cylinder>
            <length>0.02</length>
            <radius>0.01</radius>
          </cylinder>
        </geometry>
      </visual>
    </link>
    <joint name='arm_right_2_joint' type='revolute'>
      <child>arm_right_2_link</child>
      <parent>arm_right_1_link</parent>
      <axis>
        <xyz>1 0 0</xyz>
        <limit>
          <lower>-1.5708</lower>
          <upper>1.5708</upper>
          <effort>50</effort>
          <velocity>4</velocity>
        </limit>
        <dynamics>
          <spring_reference>0</spring_reference>
          <spring_stiffness>0</spring_stiffness>
        </dynamics>
        <use_parent_model_frame>1</use_parent_model_frame>
      </axis>
    </joint>
    <link name='arm_right_3_link'>
      <pose frame=''>0 -0.14659 0.2805 0 -0 0</pose>
      <inertial>
        <pose frame=''>0 -0.0225 0 0 -0 0</pose>
        <mass>0.11802</mass>
        <inertia>
          <ixx>0.0027035</ixx>
          <ixy>3.028e-08</ixy>
          <ixz>0.000800445</ixz>
          <iyy>0.00370572</iyy>
          <iyz>1.01426e-06</iyz>
          <izz>0.00174437</izz>
        </inertia>
      </inertial>
      <collision name='arm_right_3_link_fixed_joint_lump__gripper_right_link_collision'>
        <pose frame=''>0 -0.045 0 0 -0 0</pose>
        <geometry>
          <box>
            <size>0.04 0.09 0.02</size>
          </box>
        </geometry>
      </collision>
      <visual name='arm_right_3_link_visual'>
        <pose frame=''>0 0 0 3.14159 1.57079 3.14159</pose>
        <geometry>
          <cylinder>
            <length>0.02</length>
            <radius>0.01</radius>
          </cylinder>
        </geometry>
      </visual>
      <visual name='arm_right_3_link_fixed_joint_lump__gripper_right_link_visual_1'>
        <pose frame=''>0 -0.045 0 0 -0 0</pose>
        <geometry>
          <box>
            <size>0.04 0.09 0.02</size>
          </box>
        </geometry>
      </visual>
    </link>
    <joint name='arm_right_3_joint' type='revolute'>
      <child>arm_right_3_link</child>
      <parent>arm_right_2_link</parent>
      <axis>
        <xyz>1 0 0</xyz>
        <limit>
          <lower>-1.5708</lower>
          <upper>1.5708</upper>
          <effort>50</effort>
          <velocity>4</velocity>
        </limit>
        <dynamics>
          <spring_reference>0</spring_reference>
          <spring_stiffness>0</spring_stiffness>
        </dynamics>
        <use_parent_model_frame>1</use_parent_model_frame>
      </axis>
    </joint>
    <link name='leg_left_1_link'>
      <pose frame=''>0 0.0315 0.2025 0 -0 0</pose>
      <inertial>
        <pose frame=''>0 0 0 0 -0 0</pose>
        <mass>0.02901</mass>
        <inertia>
          <ixx>0.00132188</ixx>
          <ixy>1.514e-08</ixy>
          <ixz>0.000400223</ixz>
          <iyy>0.00185286</iyy>
          <iyz>5.0713e-07</iyz>
          <izz>0.000842313</izz>
        </inertia>
      </inertial>
      <collision name='leg_left_1_link_collision'>
        <pose frame=''>0 0 0 3.14159 1.57079 3.14159</pose>
        <geometry>
          <cylinder>
            <length>0.02</length>
            <radius>0.01</radius>
          </cylinder>
        </geometry>
        <surface>
          <contact>
            <ode/>
          </contact>
          <friction>
            <ode>
              <mu>0.9</mu>
              <mu2>0.9</mu2>
            </ode>
          </friction>
        </surface>
      </collision>
      <visual name='leg_left_1_link_visual'>
        <pose frame=''>0 0 0 3.14159 1.57079 3.14159</pose>
        <geometry>
          <cylinder>
            <length>0.02</length>
            <radius>0.01</radius>
          </cylinder>
        </geometry>
        <material>
          <script>
            <uri>__default__</uri>
            <name>__default__</name>
          </script>
        </material>
      </visual>
      <gravity>1</gravity>
      <velocity_decay/>
    </link>
    <joint name='leg_left_1_joint' type='revolute'>
      <child>leg_left_1_link</child>
      <parent>base_link</parent>
      <axis>
        <xyz>1 0 0</xyz>
        <limit>
          <lower>-1.2</lower>
          <upper>1.2</upper>
          <effort>50</effort>
          <velocity>4</velocity>
        </limit>
        <dynamics>
          <spring_reference>0</spring_reference>
          <spring_stiffness>0</spring_stiffness>
        </dynamics>
        <use_parent_model_frame>1</use_parent_model_frame>
      </axis>
      <physics>
        <ode>
          <implicit_spring_damper>1</implicit_spring_damper>
          <cfm_damping>1</cfm_damping>
          <limit>
            <cfm>0</cfm>
            <erp>0.2</erp>
          </limit>
        </ode>
      </physics>
    </joint>
    <link name='leg_left_2_link'>
      <pose frame=''>0 0.0315 0.15543 0 -0 0</pose>
      <inertial>
        <pose frame=''>0.014975 0 -0.007298 0 -0 0</pose>
        <mass>0.109621</mass>
        <inertia>
          <ixx>0.00169346</ixx>
          <ixy>-5.37486e-06</ixy>
          <ixz>3.41958e-05</ixz>
          <iyy>0.000848847</iyy>
          <iyz>5.33794e-05</iyz>
          <izz>0.00172672</izz>
        </inertia>
      </inertial>
      <collision name='leg_left_2_link_collision'>
        <pose frame=''>0.02 0 0 0 0.463647 0</pose>
        <geometry>
          <box>
            <size>0.02 0.04 0.02</size>
          </box>
        </geometry>
      </collision>
      <collision name='leg_left_2_link_fixed_joint_lump__leg_left_3a_link_collision_1'>
        <pose frame=''>0.04104 0 -0.016 0 -0 0</pose>
        <geometry>
          <box>
            <size>0.02 0.04 0.025</size>
          </box>
        </geometry>
      </collision>
      <visual name='leg_left_2_link_visual'>
        <pose frame=''>0.02 0 0 0 0.463647 0</pose>
        <geometry>
          <box>
            <size>0.02 0.04 0.02</size>
          </box>
        </geometry>
      </visual>
      <visual name='leg_left_2_link_fixed_joint_lump__leg_left_3a_link_visual_1'>
        <pose frame=''>0.04104 0 -0.016 0 -0 0</pose>
        <geometry>
          <box>
            <size>0.02 0.04 0.025</size>
          </box>
        </geometry>
      </visual>
    </link>
    <joint name='leg_left_2_joint' type='revolute'>
      <child>leg_left_2_link</child>
      <parent>leg_left_1_link</parent>
      <axis>
        <xyz>0 1 0</xyz>
        <limit>
          <lower>-1.2</lower>
          <upper>1.2</upper>
          <effort>50</effort>
          <velocity>4</velocity>
        </limit>
        <dynamics>
          <spring_reference>0</spring_reference>
          <spring_stiffness>0</spring_stiffness>
        </dynamics>
        <use_parent_model_frame>1</use_parent_model_frame>
      </axis>
      <physics>
        <ode>
          <implicit_spring_damper>1</implicit_spring_damper>
          <cfm_damping>1</cfm_damping>
          <limit>
            <cfm>0</cfm>
            <erp>0.2</erp>
          </limit>
        </ode>
      </physics>
    </joint>
    <link name='leg_left_3_link'>
      <pose frame=''>0.04104 0.0315 0.11066 0 -0 0</pose>
      <inertial>
        <pose frame=''>0 0 0 0 -0 0</pose>
        <mass>0.05</mass>
        <inertia>
          <ixx>0.000841648</ixx>
          <ixy>-2.68743e-06</ixy>
          <ixz>6.67199e-06</ixz>
          <iyy>0.000397948</iyy>
          <iyz>2.66897e-05</iyz>
          <izz>0.000841967</izz>
        </inertia>
      </inertial>
      <collision name='leg_left_3_link_collision'>
        <pose frame=''>0 0 -0.02 0 -0 0</pose>
        <geometry>
          <box>
            <size>0.02 0.04 0.04</size>
          </box>
        </geometry>
      </collision>
      <visual name='leg_left_3_link_visual'>
        <pose frame=''>0 0 -0.02 0 -0 0</pose>
        <geometry>
          <box>
            <size>0.02 0.04 0.04</size>
          </box>
        </geometry>
      </visual>
    </link>
    <joint name='leg_left_3_joint' type='revolute'>
      <child>leg_left_3_link</child>
      <parent>leg_left_2_link</parent>
      <axis>
        <xyz>0 1 0</xyz>
        <limit>
          <lower>-1.2</lower>
          <upper>1.2</upper>
          <effort>50</effort>
          <velocity>4</velocity>
        </limit>
        <dynamics>
          <spring_reference>0</spring_reference>
          <spring_stiffness>0</spring_stiffness>
        </dynamics>
        <use_parent_model_frame>1</use_parent_model_frame>
      </axis>
      <physics>
        <ode>
          <implicit_spring_damper>1</implicit_spring_damper>
          <cfm_damping>1</cfm_damping>
          <limit>
            <cfm>0</cfm>
            <erp>0.2</erp>
          </limit>
        </ode>
      </physics>
    </joint>
    <link name='leg_left_4_link'>
      <pose frame=''>0.04104 0.0315 0.0521 0 -0 0</pose>
      <inertial>
        <pose frame=''>0 0 0 0 -0 0</pose>
        <mass>0.06</mass>
        <inertia>
          <ixx>0.000841648</ixx>
          <ixy>-2.68743e-06</ixy>
          <ixz>6.67199e-06</ixz>
          <iyy>0.000397948</iyy>
          <iyz>2.66897e-05</iyz>
          <izz>0.000841967</izz>
        </inertia>
      </inertial>
      <collision name='leg_left_4_link_collision'>
        <pose frame=''>0 0 0 1.5708 -0 0</pose>
        <geometry>
          <cylinder>
            <length>0.02</length>
            <radius>0.01</radius>
          </cylinder>
        </geometry>
      </collision>
      <visual name='leg_left_4_link_visual'>
        <pose frame=''>0 0 0 1.5708 -0 0</pose>
        <geometry>
          <cylinder>
            <length>0.02</length>
            <radius>0.01</radius>
          </cylinder>
        </geometry>
      </visual>
    </link>
    <joint name='leg_left_4_joint' type='revolute'>
      <child>leg_left_4_link</child>
      <parent>leg_left_3_link</parent>
      <axis>
        <xyz>0 1 0</xyz>
        <limit>
          <lower>-1.2</lower>
          <upper>1.2</upper>
          <effort>50</effort>
          <velocity>4</velocity>
        </limit>
        <dynamics>
          <damping>1</damping>
          <friction>1</friction>
          <spring_reference>0</spring_reference>
          <spring_stiffness>0</spring_stiffness>
        </dynamics>
        <use_parent_model_frame>1</use_parent_model_frame>
      </axis>
      <physics>
        <ode>
          <implicit_spring_damper>1</implicit_spring_damper>
          <cfm_damping>1</cfm_damping>
          <limit>
            <cfm>0</cfm>
            <erp>0.2</erp>
          </limit>
        </ode>
      </physics>
    </joint>
    <link name='leg_left_5_link'>
      <pose frame=''>0.04104 0.0315 0.00503 0 -0 0</pose>
      <inertial>
        <pose frame=''>0 0 0 0 -0 0</pose>
        <mass>0.05</mass>
        <inertia>
          <ixx>0.000841648</ixx>
          <ixy>-2.68743e-06</ixy>
          <ixz>6.67199e-06</ixz>
          <iyy>0.000397948</iyy>
          <iyz>2.66897e-05</iyz>
          <izz>0.000841967</izz>
        </inertia>
      </inertial>
      <collision name='leg_left_5_link_collision'>
        <pose frame=''>0 0 -0.005 0 -0 0</pose>
        <geometry>
          <box>
            <size>0.095 0.07 0.01</size>
          </box>
        </geometry>
      </collision>
      <visual name='leg_left_5_link_visual'>
        <pose frame=''>0 0 -0.005 0 -0 0</pose>
        <geometry>
          <box>
            <size>0.095 0.07 0.01</size>
          </box>
        </geometry>
      </visual>
    </link>
    <joint name='leg_left_5_joint' type='revolute'>
      <child>leg_left_5_link</child>
      <parent>leg_left_4_link</parent>
      <axis>
        <xyz>1 0 0</xyz>
        <limit>
          <lower>-1.2</lower>
          <upper>1.2</upper>
          <effort>50</effort>
          <velocity>4</velocity>
        </limit>
        <dynamics>
          <spring_reference>0</spring_reference>
          <spring_stiffness>0</spring_stiffness>
        </dynamics>
        <use_parent_model_frame>1</use_parent_model_frame>
      </axis>
    </joint>
    <link name='leg_right_1_link'>
      <pose frame=''>0 -0.0315 0.2025 0 -0 0</pose>
      <inertial>
        <pose frame=''>0 0 0 0 -0 0</pose>
        <mass>0.02901</mass>
        <inertia>
          <ixx>0.00132188</ixx>
          <ixy>1.514e-08</ixy>
          <ixz>0.000400223</ixz>
          <iyy>0.00185286</iyy>
          <iyz>5.0713e-07</iyz>
          <izz>0.000842313</izz>
        </inertia>
      </inertial>
      <collision name='leg_right_1_link_collision'>
        <pose frame=''>0 0 0 3.14159 1.57079 3.14159</pose>
        <geometry>
          <cylinder>
            <length>0.02</length>
            <radius>0.01</radius>
          </cylinder>
        </geometry>
        <surface>
          <contact>
            <ode/>
          </contact>
          <friction>
            <ode>
              <mu>0.9</mu>
              <mu2>0.9</mu2>
            </ode>
          </friction>
        </surface>
      </collision>
      <visual name='leg_right_1_link_visual'>
        <pose frame=''>0 0 0 3.14159 1.57079 3.14159</pose>
        <geometry>
          <cylinder>
            <length>0.02</length>
            <radius>0.01</radius>
          </cylinder>
        </geometry>
        <material>
          <script>
            <uri>__default__</uri>
            <name>__default__</name>
          </script>
        </material>
      </visual>
      <gravity>1</gravity>
      <velocity_decay/>
    </link>
    <joint name='leg_right_1_joint' type='revolute'>
      <child>leg_right_1_link</child>
      <parent>base_link</parent>
      <axis>
        <xyz>1 0 0</xyz>
        <limit>
          <lower>-1.2</lower>
          <upper>1.2</upper>
          <effort>50</effort>
          <velocity>4</velocity>
        </limit>
        <dynamics>
          <spring_reference>0</spring_reference>
          <spring_stiffness>0</spring_stiffness>
        </dynamics>
        <use_parent_model_frame>1</use_parent_model_frame>
      </axis>
      <physics>
        <ode>
          <implicit_spring_damper>1</implicit_spring_damper>
          <cfm_damping>1</cfm_damping>
          <limit>
            <cfm>0</cfm>
            <erp>0.2</erp>
          </limit>
        </ode>
      </physics>
    </joint>
    <link name='leg_right_2_link'>
      <pose frame=''>0 -0.0315 0.15543 0 -0 0</pose>
      <inertial>
        <pose frame=''>0.014975 0 -0.007298 0 -0 0</pose>
        <mass>0.109621</mass>
        <inertia>
          <ixx>0.00169346</ixx>
          <ixy>-5.37486e-06</ixy>
          <ixz>3.41958e-05</ixz>
          <iyy>0.000848847</iyy>
          <iyz>5.33794e-05</iyz>
          <izz>0.00172672</izz>
        </inertia>
      </inertial>
      <collision name='leg_right_2_link_collision'>
        <pose frame=''>0.02 0 0 0 0.463647 0</pose>
        <geometry>
          <box>
            <size>0.02 0.04 0.02</size>
          </box>
        </geometry>
      </collision>
      <collision name='leg_right_2_link_fixed_joint_lump__leg_right_3a_link_collision_1'>
        <pose frame=''>0.04104 0 -0.016 0 -0 0</pose>
        <geometry>
          <box>
            <size>0.02 0.04 0.025</size>
          </box>
        </geometry>
      </collision>
      <visual name='leg_right_2_link_visual'>
        <pose frame=''>0.02 0 0 0 0.463647 0</pose>
        <geometry>
          <box>
            <size>0.02 0.04 0.02</size>
          </box>
        </geometry>
      </visual>
      <visual name='leg_right_2_link_fixed_joint_lump__leg_right_3a_link_visual_1'>
        <pose frame=''>0.04104 0 -0.016 0 -0 0</pose>
        <geometry>
          <box>
            <size>0.02 0.04 0.025</size>
          </box>
        </geometry>
      </visual>
    </link>
    <joint name='leg_right_2_joint' type='revolute'>
      <child>leg_right_2_link</child>
      <parent>leg_right_1_link</parent>
      <axis>
        <xyz>0 1 0</xyz>
        <limit>
          <lower>-1.2</lower>
          <upper>1.2</upper>
          <effort>50</effort>
          <velocity>4</velocity>
        </limit>
        <dynamics>
          <spring_reference>0</spring_reference>
          <spring_stiffness>0</spring_stiffness>
        </dynamics>
        <use_parent_model_frame>1</use_parent_model_frame>
      </axis>
      <physics>
        <ode>
          <implicit_spring_damper>1</implicit_spring_damper>
          <cfm_damping>1</cfm_damping>
          <limit>
            <cfm>0</cfm>
            <erp>0.2</erp>
          </limit>
        </ode>
      </physics>
    </joint>
    <link name='leg_right_3_link'>
      <pose frame=''>0.04104 -0.0315 0.11066 0 -0 0</pose>
      <inertial>
        <pose frame=''>0 0 0 0 -0 0</pose>
        <mass>0.05</mass>
        <inertia>
          <ixx>0.000841648</ixx>
          <ixy>-2.68743e-06</ixy>
          <ixz>6.67199e-06</ixz>
          <iyy>0.000397948</iyy>
          <iyz>2.66897e-05</iyz>
          <izz>0.000841967</izz>
        </inertia>
      </inertial>
      <collision name='leg_right_3_link_collision'>
        <pose frame=''>0 0 -0.02 0 -0 0</pose>
        <geometry>
          <box>
            <size>0.02 0.04 0.04</size>
          </box>
        </geometry>
      </collision>
      <visual name='leg_right_3_link_visual'>
        <pose frame=''>0 0 -0.02 0 -0 0</pose>
        <geometry>
          <box>
            <size>0.02 0.04 0.04</size>
          </box>
        </geometry>
      </visual>
    </link>
    <joint name='leg_right_3_joint' type='revolute'>
      <child>leg_right_3_link</child>
      <parent>leg_right_2_link</parent>
      <axis>
        <xyz>0 1 0</xyz>
        <limit>
          <lower>-1.2</lower>
          <upper>1.2</upper>
          <effort>50</effort>
          <velocity>4</velocity>
        </limit>
        <dynamics>
          <spring_reference>0</spring_reference>
          <spring_stiffness>0</spring_stiffness>
        </dynamics>
        <use_parent_model_frame>1</use_parent_model_frame>
      </axis>
      <physics>
        <ode>
          <implicit_spring_damper>1</implicit_spring_damper>
          <cfm_damping>1</cfm_damping>
          <limit>
            <cfm>0</cfm>
            <erp>0.2</erp>
          </limit>
        </ode>
      </physics>
    </joint>
    <link name='leg_right_4_link'>
      <pose frame=''>0.04104 -0.0315 0.0521 0 -0 0</pose>
      <inertial>
        <pose frame=''>0 0 0 0 -0 0</pose>
        <mass>0.06</mass>
        <inertia>
          <ixx>0.000841648</ixx>
          <ixy>-2.68743e-06</ixy>
          <ixz>6.67199e-06</ixz>
          <iyy>0.000397948</iyy>
          <iyz>2.66897e-05</iyz>
          <izz>0.000841967</izz>
        </inertia>
      </inertial>
      <collision name='leg_right_4_link_collision'>
        <pose frame=''>0 0 0 1.5708 -0 0</pose>
        <geometry>
          <cylinder>
            <length>0.02</length>
            <radius>0.01</radius>
          </cylinder>
        </geometry>
      </collision>
      <visual name='leg_right_4_link_visual'>
        <pose frame=''>0 0 0 1.5708 -0 0</pose>
        <geometry>
          <cylinder>
            <length>0.02</length>
            <radius>0.01</radius>
          </cylinder>
        </geometry>
      </visual>
    </link>
    <joint name='leg_right_4_joint' type='revolute'>
      <child>leg_right_4_link</child>
      <parent>leg_right_3_link</parent>
      <axis>
        <xyz>0 1 0</xyz>
        <limit>
          <lower>-1.2</lower>
          <upper>1.2</upper>
          <effort>50</effort>
          <velocity>4</velocity>
        </limit>
        <dynamics>
          <damping>1</damping>
          <friction>1</friction>
          <spring_reference>0</spring_reference>
          <spring_stiffness>0</spring_stiffness>
        </dynamics>
        <use_parent_model_frame>1</use_parent_model_frame>
      </axis>
      <physics>
        <ode>
          <implicit_spring_damper>1</implicit_spring_damper>
          <cfm_damping>1</cfm_damping>
          <limit>
            <cfm>0</cfm>
            <erp>0.2</erp>
          </limit>
        </ode>
      </physics>
    </joint>
    <link name='leg_right_5_link'>
      <pose frame=''>0.04104 -0.0315 0.00503 0 -0 0</pose>
      <inertial>
        <pose frame=''>0 0 0 0 -0 0</pose>
        <mass>0.05</mass>
        <inertia>
          <ixx>0.000841648</ixx>
          <ixy>-2.68743e-06</ixy>
          <ixz>6.67199e-06</ixz>
          <iyy>0.000397948</iyy>
          <iyz>2.66897e-05</iyz>
          <izz>0.000841967</izz>
        </inertia>
      </inertial>
      <collision name='leg_right_5_link_collision'>
        <pose frame=''>0 0 -0.005 0 -0 0</pose>
        <geometry>
          <box>
            <size>0.095 0.07 0.01</size>
          </box>
        </geometry>
      </collision>
      <visual name='leg_right_5_link_visual'>
        <pose frame=''>0 0 -0.005 0 -0 0</pose>
        <geometry>
          <box>
            <size>0.095 0.07 0.01</size>
          </box>
        </geometry>
      </visual>
    </link>
    <joint name='leg_right_5_joint' type='revolute'>
      <child>leg_right_5_link</child>
      <parent>leg_right_4_link</parent>
      <axis>
        <xyz>1 0 0</xyz>
        <limit>
          <lower>-1.2</lower>
          <upper>1.2</upper>
          <effort>50</effort>
          <velocity>4</velocity>
        </limit>
        <dynamics>
          <spring_reference>0</spring_reference>
          <spring_stiffness>0</spring_stiffness>
        </dynamics>
        <use_parent_model_frame>1</use_parent_model_frame>
      </axis>
    </joint>
    <plugin name='my_joint_state_publisher' filename='libmy_joint_state_publisher.so'>
      <robot_name>lobot</robot_name>
      <update_rate>500</update_rate>
    </plugin>
    <static>0</static>
    <plugin name='robot_plugin_lobot' filename='librobot_plugin.so'>
      <robot_name>lobot</robot_name>
      <update_rate>100</update_rate>
    </plugin>
  </model>
</sdf>
