<?xml version="1.0" encoding="utf-8"?>
<!-- =================================================================================== -->
<!-- |    This document was autogenerated by xacro from /home/pohzhiee/catkin_ws/src/lobot_description/robots/biped_test.urdf.xacro | -->
<!-- |    EDITING THIS FILE BY HAND IS NOT RECOMMENDED                                 | -->
<!-- =================================================================================== -->
<robot name="lobot" xmlns:xacro="http://ros.org/wiki/xacro">
  <material name="Blue">
    <color rgba="0.0 0.0 0.8 1.0"/>
  </material>
  <material name="Green">
    <color rgba="0.0 0.8 0.0 1.0"/>
  </material>
  <material name="Grey">
    <color rgba="0.7 0.7 0.7 1.0"/>
  </material>
  <material name="LightGrey">
    <color rgba="0.9 0.9 0.9 1.0"/>
  </material>
  <material name="DarkGrey">
    <color rgba="0.2 0.2 0.2 1.0"/>
  </material>
  <material name="Red">
    <color rgba="0.8 0.0 0.0 1.0"/>
  </material>
  <material name="White">
    <color rgba="1.0 1.0 1.0 1.0"/>
  </material>
  <link name="world"/>
  <joint name="world_joint" type="fixed">
    <parent link="world"/>
    <child link="base_link"/>
    <origin rpy="0 0 0" xyz="0  0 0.25"/>
  </joint>
  <link name="base_link">
    <inertial>
      <mass value="0.083221"/>
      <origin rpy="0 0 0" xyz="-0.01209 -0.00442 0.02145"/>
      <inertia ixx="0.03408839175" ixy="0.00000898087" ixz="0.00238269732" iyy="0.03351929137" iyz="0.00049460232" izz="0.04506059363"/>
    </inertial>
    <visual>
      <origin rpy="0 0 0" xyz="0 0 0"/>
      <geometry>
        <box size="0.043 0.118 0.095"/>
      </geometry>
      <material name="LightGrey"/>
    </visual>
    <collision>
      <origin rpy="0 0 0" xyz="0 0 0"/>
      <geometry>
        <box size="0.043 0.118 0.095"/>
      </geometry>
    </collision>
  </link>
  <link name="IMU_link">
    <inertial>
      <mass value="0.0001"/>
      <origin rpy="0 0 0" xyz="0 0 0"/>
      <inertia ixx="0.0001" ixy="0" ixz="0" iyy="0.000001" iyz="0" izz="0.0001"/>
    </inertial>
    <visual>
      <origin rpy="0 0 0" xyz="0 0 0"/>
      <geometry>
        <box size="0.001 0.001 0.001"/>
      </geometry>
      <material name="red"/>
    </visual>
    <collision>
      <origin rpy="0 0 0" xyz="0 0 0"/>
      <geometry>
        <box size=".001 .001 .001"/>
      </geometry>
    </collision>
  </link>
  <joint name="IMU_joint" type="fixed">
    <axis xyz="1 0 0"/>
    <origin xyz="0 0 0"/>
    <parent link="base_link"/>
    <child link="IMU_link"/>
  </joint>
  <!--Constant parameters-->
  <gazebo>
    <plugin filename="libmy_joint_state_publisher.so" name="my_joint_state_publisher">
      <robot_name>lobot</robot_name>
      <update_rate>500</update_rate>
    </plugin>
  </gazebo>
  <gazebo>
    <plugin filename="librobot_plugin.so" name="robot_plugin_lobot">
      <robot_name>lobot</robot_name>
      <update_rate>1000</update_rate>
    </plugin>
  </gazebo>
  <gazebo reference="IMU_link">
    <sensor name="IMU_lobot" type="imu">
      <always_on>true</always_on>
      <update_rate>10.0</update_rate>
      <plugin filename="libgazebo_ros_imu_sensor.so" name="lobot_IMU_controller"/>
    </sensor>
  </gazebo>
  <link name="leg_right_1_link">
    <inertial>
      <mass value="0.02901"/>
      <origin rpy="0.0 0.0 0.0" xyz="0 0 0"/>
      <inertia ixx="0.00132187534" ixy="0.00000001514" ixz="0.00040022268" iyy="0.0018528617" iyz="0.00000050713" izz="0.00084231334"/>
    </inertial>
    <visual>
      <origin rpy="0 1.57079632679 0" xyz="0 0 0"/>
      <geometry>
        <cylinder length="0.02" radius="0.01"/>
      </geometry>
      <material name="LightGrey"/>
    </visual>
    <collision>
      <origin rpy="0 1.57079632679 0" xyz="0 0 0"/>
      <geometry>
        <cylinder length="0.02" radius="0.01"/>
      </geometry>
    </collision>
  </link>
  <joint name="leg_right_1_joint" type="revolute">
    <origin rpy="0 0 0" xyz="0  -0.0315 -0.0475"/>
    <axis xyz="1 0 0"/>
    <parent link="base_link"/>
    <child link="leg_right_1_link"/>
    <limit effort="50" lower="-1.2" upper="1.2" velocity="4"/>
  </joint>
  <link name="leg_right_2_link">
    <inertial>
      <mass value="0.069621"/>
      <origin rpy="0.0 0.0 0.0" xyz="0 0 0"/>
      <inertia ixx="0.0008416476" ixy="-0.00000268743" ixz="0.00000667199" iyy="0.00039794844" iyz="0.00002668971" izz="0.00084196694"/>
    </inertial>
    <visual>
      <origin rpy="0 0.463646715792 0" xyz="0.02 0 0"/>
      <geometry>
        <!-- <cylinder radius="0.01" length="0.02" /> -->
        <box size="0.02 0.04 0.02"/>
      </geometry>
      <material name="LightGrey"/>
    </visual>
    <collision>
      <origin rpy="0 0.463646715792 0" xyz="0.02 0 0"/>
      <geometry>
        <box size="0.02 0.04 0.02"/>
      </geometry>
    </collision>
  </link>
  <joint name="leg_right_2_joint" type="revolute">
    <origin rpy="0 0 0" xyz="0 0 -0.04707"/>
    <axis xyz="0 1 0"/>
    <parent link="leg_right_1_link"/>
    <child link="leg_right_2_link"/>
    <limit effort="50" lower="-1.2" upper="1.2" velocity="4"/>
  </joint>
  <link name="leg_right_3a_link">
    <inertial>
      <mass value="0.04"/>
      <origin rpy="0.0 0.0 0.0" xyz="0 0 0"/>
      <inertia ixx="0.0008416476" ixy="-0.00000268743" ixz="0.00000667199" iyy="0.00039794844" iyz="0.00002668971" izz="0.00084196694"/>
    </inertial>
    <visual>
      <origin rpy="0 0 0" xyz="0 0 0.004"/>
      <geometry>
        <box size="0.02 0.04 0.025"/>
      </geometry>
      <material name="LightGrey"/>
    </visual>
    <collision>
      <origin rpy="0 0 0" xyz="0 0 0.004"/>
      <geometry>
        <box size="0.02 0.04 0.025"/>
      </geometry>
    </collision>
  </link>
  <joint name="leg_right_3a_joint" type="fixed">
    <origin rpy="0 0 0" xyz="0.04104 0 -0.020"/>
    <parent link="leg_right_2_link"/>
    <child link="leg_right_3a_link"/>
  </joint>
  <link name="leg_right_3_link">
    <inertial>
      <mass value="0.05"/>
      <origin rpy="0.0 0.0 0.0" xyz="0 0 0"/>
      <inertia ixx="0.0008416476" ixy="-0.00000268743" ixz="0.00000667199" iyy="0.00039794844" iyz="0.00002668971" izz="0.00084196694"/>
    </inertial>
    <visual>
      <origin rpy="0 0 0" xyz="0 0 -0.02"/>
      <geometry>
        <box size="0.02 0.04 0.04"/>
      </geometry>
      <material name="LightGrey"/>
    </visual>
    <collision>
      <origin rpy="0 0 0" xyz="0 0 -0.02"/>
      <geometry>
        <box size="0.02 0.04 0.04"/>
      </geometry>
    </collision>
  </link>
  <joint name="leg_right_3_joint" type="revolute">
    <origin rpy="0 0 0" xyz="0 0 -0.02477"/>
    <axis xyz="0 1 0"/>
    <parent link="leg_right_3a_link"/>
    <child link="leg_right_3_link"/>
    <limit effort="50" lower="-1.2" upper="1.2" velocity="4"/>
  </joint>
  <link name="leg_right_4_link">
    <inertial>
      <mass value="0.06"/>
      <origin rpy="0.0 0.0 0.0" xyz="0 0 0"/>
      <inertia ixx="0.0008416476" ixy="-0.00000268743" ixz="0.00000667199" iyy="0.00039794844" iyz="0.00002668971" izz="0.00084196694"/>
    </inertial>
    <visual>
      <origin rpy="1.57079632679 0 0" xyz="0 0 0"/>
      <geometry>
        <cylinder length="0.02" radius="0.01"/>
      </geometry>
      <material name="LightGrey"/>
    </visual>
    <collision>
      <origin rpy="1.57079632679 0 0" xyz="0 0 0"/>
      <geometry>
        <cylinder length="0.02" radius="0.01"/>
      </geometry>
    </collision>
  </link>
  <joint name="leg_right_4_joint" type="revolute">
    <origin rpy="0 0 0" xyz="0 0 -0.05856"/>
    <axis xyz="0 1 0"/>
    <parent link="leg_right_3_link"/>
    <child link="leg_right_4_link"/>
    <dynamics damping="1.0" friction="1.0"/>
    <limit effort="50" lower="-1.2" upper="1.2" velocity="4"/>
  </joint>
  <link name="leg_right_5_link">
    <inertial>
      <mass value="0.05"/>
      <origin rpy="0.0 0.0 0.0" xyz="0 0 0"/>
      <inertia ixx="0.0008416476" ixy="-0.00000268743" ixz="0.00000667199" iyy="0.00039794844" iyz="0.00002668971" izz="0.00084196694"/>
    </inertial>
    <visual>
      <origin rpy="0 0 0" xyz="0 0 -0.005"/>
      <geometry>
        <!-- <cylinder radius="0.01" length="0.02" /> -->
        <box size="0.095 0.07 0.01"/>
      </geometry>
      <material name="LightGrey"/>
    </visual>
    <collision>
      <origin rpy="0 0 0" xyz="0 0 -0.005"/>
      <geometry>
        <box size="0.095 0.07 0.01"/>
      </geometry>
    </collision>
  </link>
  <joint name="leg_right_5_joint" type="revolute">
    <origin rpy="0 0 0" xyz="0 0 -0.04707"/>
    <axis xyz="1 0 0"/>
    <parent link="leg_right_4_link"/>
    <child link="leg_right_5_link"/>
    <limit effort="50" lower="-1.2" upper="1.2" velocity="4"/>
  </joint>
  <gazebo reference="leg_right_1_link">
    <mu1>0.9</mu1>
    <mu2>0.9</mu2>
  </gazebo>
  <gazebo reference="leg_right_1_joint">
    <implicitSpringDamper>1</implicitSpringDamper>
  </gazebo>
  <gazebo reference="leg_right_2_joint">
    <implicitSpringDamper>1</implicitSpringDamper>
  </gazebo>
  <gazebo reference="leg_right_3_joint">
    <implicitSpringDamper>1</implicitSpringDamper>
  </gazebo>
  <gazebo reference="leg_right_4_joint">
    <implicitSpringDamper>1</implicitSpringDamper>
  </gazebo>
  <!--
        <gazebo reference="leg_${side}_5_joint">
            <implicitSpringDamper>1</implicitSpringDamper>
        </gazebo>
        <gazebo reference="leg_${side}_6_joint">
            <implicitSpringDamper>1</implicitSpringDamper>
            <provideFeedback>1</provideFeedback>
        </gazebo> -->
  <transmission name="leg_right_1_trans">
    <type>transmission_interface/SimpleTransmission</type>
    <actuator name="leg_right_1_motor">
      <mechanicalReduction>1.0</mechanicalReduction>
    </actuator>
    <joint name="leg_right_1_joint">
      <hardwareInterface>hardware_interface/JointCommandHandle</hardwareInterface>
    </joint>
  </transmission>
  <transmission name="leg_right_2_trans">
    <type>transmission_interface/SimpleTransmission</type>
    <actuator name="leg_right_2_motor">
      <mechanicalReduction>1.0</mechanicalReduction>
    </actuator>
    <joint name="leg_right_2_joint">
      <hardwareInterface>hardware_interface/JointCommandHandle</hardwareInterface>
    </joint>
  </transmission>
  <transmission name="leg_right_3_trans">
    <type>transmission_interface/SimpleTransmission</type>
    <actuator name="leg_right_3_motor">
      <mechanicalReduction>1.0</mechanicalReduction>
    </actuator>
    <joint name="leg_right_3_joint">
      <hardwareInterface>hardware_interface/JointCommandHandle</hardwareInterface>
    </joint>
  </transmission>
  <transmission name="leg_right_4_trans">
    <type>transmission_interface/SimpleTransmission</type>
    <actuator name="leg_right_4_motor">
      <mechanicalReduction>1.0</mechanicalReduction>
    </actuator>
    <joint name="leg_right_4_joint">
      <hardwareInterface>hardware_interface/JointCommandHandle</hardwareInterface>
    </joint>
  </transmission>
  <transmission name="leg_right_5_trans">
    <type>transmission_interface/SimpleTransmission</type>
    <actuator name="leg_right_5_motor">
      <mechanicalReduction>1.0</mechanicalReduction>
    </actuator>
    <joint name="leg_right_5_joint">
      <hardwareInterface>hardware_interface/JointCommandHandle</hardwareInterface>
    </joint>
  </transmission>
  <!-- 
        <xacro:lobot_leg_simple_transmission name="${name}" side="${side}" number="5" reduction="${leg_reduction}" />
        <xacro:lobot_leg_simple_transmission name="${name}" side="${side}" number="6" reduction="${leg_reduction}" />
        -->
  <link name="leg_left_1_link">
    <inertial>
      <mass value="0.02901"/>
      <origin rpy="0.0 0.0 0.0" xyz="0 0 0"/>
      <inertia ixx="0.00132187534" ixy="0.00000001514" ixz="0.00040022268" iyy="0.0018528617" iyz="0.00000050713" izz="0.00084231334"/>
    </inertial>
    <visual>
      <origin rpy="0 1.57079632679 0" xyz="0 0 0"/>
      <geometry>
        <cylinder length="0.02" radius="0.01"/>
      </geometry>
      <material name="LightGrey"/>
    </visual>
    <collision>
      <origin rpy="0 1.57079632679 0" xyz="0 0 0"/>
      <geometry>
        <cylinder length="0.02" radius="0.01"/>
      </geometry>
    </collision>
  </link>
  <joint name="leg_left_1_joint" type="revolute">
    <origin rpy="0 0 0" xyz="0  0.0315 -0.0475"/>
    <axis xyz="1 0 0"/>
    <parent link="base_link"/>
    <child link="leg_left_1_link"/>
    <limit effort="50" lower="-1.2" upper="1.2" velocity="4"/>
  </joint>
  <link name="leg_left_2_link">
    <inertial>
      <mass value="0.069621"/>
      <origin rpy="0.0 0.0 0.0" xyz="0 0 0"/>
      <inertia ixx="0.0008416476" ixy="-0.00000268743" ixz="0.00000667199" iyy="0.00039794844" iyz="0.00002668971" izz="0.00084196694"/>
    </inertial>
    <visual>
      <origin rpy="0 0.463646715792 0" xyz="0.02 0 0"/>
      <geometry>
        <!-- <cylinder radius="0.01" length="0.02" /> -->
        <box size="0.02 0.04 0.02"/>
      </geometry>
      <material name="LightGrey"/>
    </visual>
    <collision>
      <origin rpy="0 0.463646715792 0" xyz="0.02 0 0"/>
      <geometry>
        <box size="0.02 0.04 0.02"/>
      </geometry>
    </collision>
  </link>
  <joint name="leg_left_2_joint" type="revolute">
    <origin rpy="0 0 0" xyz="0 0 -0.04707"/>
    <axis xyz="0 1 0"/>
    <parent link="leg_left_1_link"/>
    <child link="leg_left_2_link"/>
    <limit effort="50" lower="-1.2" upper="1.2" velocity="4"/>
  </joint>
  <link name="leg_left_3a_link">
    <inertial>
      <mass value="0.04"/>
      <origin rpy="0.0 0.0 0.0" xyz="0 0 0"/>
      <inertia ixx="0.0008416476" ixy="-0.00000268743" ixz="0.00000667199" iyy="0.00039794844" iyz="0.00002668971" izz="0.00084196694"/>
    </inertial>
    <visual>
      <origin rpy="0 0 0" xyz="0 0 0.004"/>
      <geometry>
        <box size="0.02 0.04 0.025"/>
      </geometry>
      <material name="LightGrey"/>
    </visual>
    <collision>
      <origin rpy="0 0 0" xyz="0 0 0.004"/>
      <geometry>
        <box size="0.02 0.04 0.025"/>
      </geometry>
    </collision>
  </link>
  <joint name="leg_left_3a_joint" type="fixed">
    <origin rpy="0 0 0" xyz="0.04104 0 -0.020"/>
    <parent link="leg_left_2_link"/>
    <child link="leg_left_3a_link"/>
  </joint>
  <link name="leg_left_3_link">
    <inertial>
      <mass value="0.05"/>
      <origin rpy="0.0 0.0 0.0" xyz="0 0 0"/>
      <inertia ixx="0.0008416476" ixy="-0.00000268743" ixz="0.00000667199" iyy="0.00039794844" iyz="0.00002668971" izz="0.00084196694"/>
    </inertial>
    <visual>
      <origin rpy="0 0 0" xyz="0 0 -0.02"/>
      <geometry>
        <box size="0.02 0.04 0.04"/>
      </geometry>
      <material name="LightGrey"/>
    </visual>
    <collision>
      <origin rpy="0 0 0" xyz="0 0 -0.02"/>
      <geometry>
        <box size="0.02 0.04 0.04"/>
      </geometry>
    </collision>
  </link>
  <joint name="leg_left_3_joint" type="revolute">
    <origin rpy="0 0 0" xyz="0 0 -0.02477"/>
    <axis xyz="0 1 0"/>
    <parent link="leg_left_3a_link"/>
    <child link="leg_left_3_link"/>
    <limit effort="50" lower="-1.2" upper="1.2" velocity="4"/>
  </joint>
  <link name="leg_left_4_link">
    <inertial>
      <mass value="0.06"/>
      <origin rpy="0.0 0.0 0.0" xyz="0 0 0"/>
      <inertia ixx="0.0008416476" ixy="-0.00000268743" ixz="0.00000667199" iyy="0.00039794844" iyz="0.00002668971" izz="0.00084196694"/>
    </inertial>
    <visual>
      <origin rpy="1.57079632679 0 0" xyz="0 0 0"/>
      <geometry>
        <cylinder length="0.02" radius="0.01"/>
      </geometry>
      <material name="LightGrey"/>
    </visual>
    <collision>
      <origin rpy="1.57079632679 0 0" xyz="0 0 0"/>
      <geometry>
        <cylinder length="0.02" radius="0.01"/>
      </geometry>
    </collision>
  </link>
  <joint name="leg_left_4_joint" type="revolute">
    <origin rpy="0 0 0" xyz="0 0 -0.05856"/>
    <axis xyz="0 1 0"/>
    <parent link="leg_left_3_link"/>
    <child link="leg_left_4_link"/>
    <dynamics damping="1.0" friction="1.0"/>
    <limit effort="50" lower="-1.2" upper="1.2" velocity="4"/>
  </joint>
  <link name="leg_left_5_link">
    <inertial>
      <mass value="0.05"/>
      <origin rpy="0.0 0.0 0.0" xyz="0 0 0"/>
      <inertia ixx="0.0008416476" ixy="-0.00000268743" ixz="0.00000667199" iyy="0.00039794844" iyz="0.00002668971" izz="0.00084196694"/>
    </inertial>
    <visual>
      <origin rpy="0 0 0" xyz="0 0 -0.005"/>
      <geometry>
        <!-- <cylinder radius="0.01" length="0.02" /> -->
        <box size="0.095 0.07 0.01"/>
      </geometry>
      <material name="LightGrey"/>
    </visual>
    <collision>
      <origin rpy="0 0 0" xyz="0 0 -0.005"/>
      <geometry>
        <box size="0.095 0.07 0.01"/>
      </geometry>
    </collision>
  </link>
  <joint name="leg_left_5_joint" type="revolute">
    <origin rpy="0 0 0" xyz="0 0 -0.04707"/>
    <axis xyz="1 0 0"/>
    <parent link="leg_left_4_link"/>
    <child link="leg_left_5_link"/>
    <limit effort="50" lower="-1.2" upper="1.2" velocity="4"/>
  </joint>
  <gazebo reference="leg_left_1_link">
    <mu1>0.9</mu1>
    <mu2>0.9</mu2>
  </gazebo>
  <gazebo reference="leg_left_1_joint">
    <implicitSpringDamper>1</implicitSpringDamper>
  </gazebo>
  <gazebo reference="leg_left_2_joint">
    <implicitSpringDamper>1</implicitSpringDamper>
  </gazebo>
  <gazebo reference="leg_left_3_joint">
    <implicitSpringDamper>1</implicitSpringDamper>
  </gazebo>
  <gazebo reference="leg_left_4_joint">
    <implicitSpringDamper>1</implicitSpringDamper>
  </gazebo>
  <!--
        <gazebo reference="leg_${side}_5_joint">
            <implicitSpringDamper>1</implicitSpringDamper>
        </gazebo>
        <gazebo reference="leg_${side}_6_joint">
            <implicitSpringDamper>1</implicitSpringDamper>
            <provideFeedback>1</provideFeedback>
        </gazebo> -->
  <transmission name="leg_left_1_trans">
    <type>transmission_interface/SimpleTransmission</type>
    <actuator name="leg_left_1_motor">
      <mechanicalReduction>1.0</mechanicalReduction>
    </actuator>
    <joint name="leg_left_1_joint">
      <hardwareInterface>hardware_interface/JointCommandHandle</hardwareInterface>
    </joint>
  </transmission>
  <transmission name="leg_left_2_trans">
    <type>transmission_interface/SimpleTransmission</type>
    <actuator name="leg_left_2_motor">
      <mechanicalReduction>1.0</mechanicalReduction>
    </actuator>
    <joint name="leg_left_2_joint">
      <hardwareInterface>hardware_interface/JointCommandHandle</hardwareInterface>
    </joint>
  </transmission>
  <transmission name="leg_left_3_trans">
    <type>transmission_interface/SimpleTransmission</type>
    <actuator name="leg_left_3_motor">
      <mechanicalReduction>1.0</mechanicalReduction>
    </actuator>
    <joint name="leg_left_3_joint">
      <hardwareInterface>hardware_interface/JointCommandHandle</hardwareInterface>
    </joint>
  </transmission>
  <transmission name="leg_left_4_trans">
    <type>transmission_interface/SimpleTransmission</type>
    <actuator name="leg_left_4_motor">
      <mechanicalReduction>1.0</mechanicalReduction>
    </actuator>
    <joint name="leg_left_4_joint">
      <hardwareInterface>hardware_interface/JointCommandHandle</hardwareInterface>
    </joint>
  </transmission>
  <transmission name="leg_left_5_trans">
    <type>transmission_interface/SimpleTransmission</type>
    <actuator name="leg_left_5_motor">
      <mechanicalReduction>1.0</mechanicalReduction>
    </actuator>
    <joint name="leg_left_5_joint">
      <hardwareInterface>hardware_interface/JointCommandHandle</hardwareInterface>
    </joint>
  </transmission>
  <!-- 
        <xacro:lobot_leg_simple_transmission name="${name}" side="${side}" number="5" reduction="${leg_reduction}" />
        <xacro:lobot_leg_simple_transmission name="${name}" side="${side}" number="6" reduction="${leg_reduction}" />
        -->
  <link name="arm_right_1_link">
    <inertial>
      <mass value="0.05901"/>
      <origin rpy="0 0 0" xyz="0 0 0"/>
      <inertia ixx="0.00132187534" ixy="0.00000001514" ixz="0.00040022268" iyy="0.0018528617" iyz="0.00000050713" izz="0.00084231334"/>
    </inertial>
    <visual>
      <origin rpy="1.57079632679 0 0" xyz="0 0 0"/>
      <geometry>
        <cylinder length="0.02" radius="0.01"/>
      </geometry>
      <material name="LightGrey"/>
    </visual>
    <!-- <collision>
                <origin rpy="${90*deg_to_rad} 0 0" xyz="0 0 0" />
                <geometry>
                    <cylinder radius="0.01" length="0.02" />
                </geometry>
            </collision> -->
  </link>
  <joint name="arm_right_1_joint" type="revolute">
    <origin rpy="0 0 0" xyz="0  -0.059 0.0305"/>
    <axis xyz="0 1 0"/>
    <parent link="base_link"/>
    <child link="arm_right_1_link"/>
    <limit effort="50" lower="-1.57" upper="1.57" velocity="4"/>
  </joint>
  <link name="arm_right_2_link">
    <inertial>
      <mass value="0.05901"/>
      <origin rpy="0 0 0" xyz="0 0 0"/>
      <inertia ixx="0.00132187534" ixy="0.00000001514" ixz="0.00040022268" iyy="0.0018528617" iyz="0.00000050713" izz="0.00084231334"/>
    </inertial>
    <visual>
      <origin rpy="0 1.57079632679 0" xyz="0 0 0"/>
      <geometry>
        <cylinder length="0.02" radius="0.01"/>
      </geometry>
      <material name="LightGrey"/>
    </visual>
    <!-- <collision>
                <origin rpy="${90*deg_to_rad} 0 0" xyz="0 0 0" />
                <geometry>
                    <cylinder radius="0.01" length="0.02" />
                </geometry>
            </collision> -->
  </link>
  <joint name="arm_right_2_joint" type="revolute">
    <origin rpy="0 0 0" xyz="0 -0.02903 0"/>
    <axis xyz="1 0 0"/>
    <parent link="arm_right_1_link"/>
    <child link="arm_right_2_link"/>
    <limit effort="50" lower="-1.57079632679" upper="1.57079632679" velocity="4"/>
  </joint>
  <link name="arm_right_3_link">
    <inertial>
      <mass value="0.05901"/>
      <origin rpy="0 0 0" xyz="0 0 0"/>
      <inertia ixx="0.00132187534" ixy="0.00000001514" ixz="0.00040022268" iyy="0.0018528617" iyz="0.00000050713" izz="0.00084231334"/>
    </inertial>
    <visual>
      <origin rpy="0 1.57079632679 0" xyz="0 0 0"/>
      <geometry>
        <cylinder length="0.02" radius="0.01"/>
      </geometry>
      <material name="LightGrey"/>
    </visual>
    <!-- <collision>
                    <origin rpy="${90*deg_to_rad} 0 0" xyz="0 0 0" />
                    <geometry>
                        <cylinder radius="0.01" length="0.02" />
                    </geometry>
                </collision> -->
  </link>
  <joint name="arm_right_3_joint" type="revolute">
    <origin rpy="0 0 0" xyz="0 -0.05856 0"/>
    <axis xyz="1 0 0"/>
    <parent link="arm_right_2_link"/>
    <child link="arm_right_3_link"/>
    <limit effort="50" lower="-1.57079632679" upper="1.57079632679" velocity="4"/>
  </joint>
  <!-- Gripper fixed link-->
  <link name="gripper_right_link">
    <inertial>
      <mass value="0.05901"/>
      <origin rpy="0 0 0" xyz="0 0 0"/>
      <inertia ixx="0.00132187534" ixy="0.00000001514" ixz="0.00040022268" iyy="0.0018528617" iyz="0.00000050713" izz="0.00084231334"/>
    </inertial>
    <visual>
      <origin rpy="0 0 0" xyz="0 0 0"/>
      <geometry>
        <box size="0.04 0.090 0.02"/>
      </geometry>
      <material name="LightGrey"/>
    </visual>
    <collision>
      <origin rpy="0 0 0" xyz="0 0 0"/>
      <geometry>
        <box size="0.04 0.090 0.02"/>
      </geometry>
    </collision>
  </link>
  <joint name="gripper_right_joint" type="fixed">
    <origin rpy="0 0 0" xyz="0 -0.045 0"/>
    <parent link="arm_right_3_link"/>
    <child link="gripper_right_link"/>
  </joint>
  <transmission name="arm_right_1_trans">
    <type>transmission_interface/SimpleTransmission</type>
    <actuator name="arm_right_1_motor">
      <mechanicalReduction>1.0</mechanicalReduction>
    </actuator>
    <joint name="arm_right_1_joint">
      <!-- <hardwareInterface>hardware_interface/PositionJointInterface</hardwareInterface> -->
      <hardwareInterface>hardware_interface/EffortJointInterface</hardwareInterface>
    </joint>
  </transmission>
  <link name="arm_left_1_link">
    <inertial>
      <mass value="0.05901"/>
      <origin rpy="0 0 0" xyz="0 0 0"/>
      <inertia ixx="0.00132187534" ixy="0.00000001514" ixz="0.00040022268" iyy="0.0018528617" iyz="0.00000050713" izz="0.00084231334"/>
    </inertial>
    <visual>
      <origin rpy="1.57079632679 0 0" xyz="0 0 0"/>
      <geometry>
        <cylinder length="0.02" radius="0.01"/>
      </geometry>
      <material name="LightGrey"/>
    </visual>
    <!-- <collision>
                <origin rpy="${90*deg_to_rad} 0 0" xyz="0 0 0" />
                <geometry>
                    <cylinder radius="0.01" length="0.02" />
                </geometry>
            </collision> -->
  </link>
  <joint name="arm_left_1_joint" type="revolute">
    <origin rpy="0 0 0" xyz="0  0.059 0.0305"/>
    <axis xyz="0 1 0"/>
    <parent link="base_link"/>
    <child link="arm_left_1_link"/>
    <limit effort="50" lower="-1.57" upper="1.57" velocity="4"/>
  </joint>
  <link name="arm_left_2_link">
    <inertial>
      <mass value="0.05901"/>
      <origin rpy="0 0 0" xyz="0 0 0"/>
      <inertia ixx="0.00132187534" ixy="0.00000001514" ixz="0.00040022268" iyy="0.0018528617" iyz="0.00000050713" izz="0.00084231334"/>
    </inertial>
    <visual>
      <origin rpy="0 1.57079632679 0" xyz="0 0 0"/>
      <geometry>
        <cylinder length="0.02" radius="0.01"/>
      </geometry>
      <material name="LightGrey"/>
    </visual>
    <!-- <collision>
                <origin rpy="${90*deg_to_rad} 0 0" xyz="0 0 0" />
                <geometry>
                    <cylinder radius="0.01" length="0.02" />
                </geometry>
            </collision> -->
  </link>
  <joint name="arm_left_2_joint" type="revolute">
    <origin rpy="0 0 0" xyz="0 0.02903 0"/>
    <axis xyz="1 0 0"/>
    <parent link="arm_left_1_link"/>
    <child link="arm_left_2_link"/>
    <limit effort="50" lower="-1.57079632679" upper="1.57079632679" velocity="4"/>
  </joint>
  <link name="arm_left_3_link">
    <inertial>
      <mass value="0.05901"/>
      <origin rpy="0 0 0" xyz="0 0 0"/>
      <inertia ixx="0.00132187534" ixy="0.00000001514" ixz="0.00040022268" iyy="0.0018528617" iyz="0.00000050713" izz="0.00084231334"/>
    </inertial>
    <visual>
      <origin rpy="0 1.57079632679 0" xyz="0 0 0"/>
      <geometry>
        <cylinder length="0.02" radius="0.01"/>
      </geometry>
      <material name="LightGrey"/>
    </visual>
    <!-- <collision>
                    <origin rpy="${90*deg_to_rad} 0 0" xyz="0 0 0" />
                    <geometry>
                        <cylinder radius="0.01" length="0.02" />
                    </geometry>
                </collision> -->
  </link>
  <joint name="arm_left_3_joint" type="revolute">
    <origin rpy="0 0 0" xyz="0 0.05856 0"/>
    <axis xyz="1 0 0"/>
    <parent link="arm_left_2_link"/>
    <child link="arm_left_3_link"/>
    <limit effort="50" lower="-1.57079632679" upper="1.57079632679" velocity="4"/>
  </joint>
  <!-- Gripper fixed link-->
  <link name="gripper_left_link">
    <inertial>
      <mass value="0.05901"/>
      <origin rpy="0 0 0" xyz="0 0 0"/>
      <inertia ixx="0.00132187534" ixy="0.00000001514" ixz="0.00040022268" iyy="0.0018528617" iyz="0.00000050713" izz="0.00084231334"/>
    </inertial>
    <visual>
      <origin rpy="0 0 0" xyz="0 0 0"/>
      <geometry>
        <box size="0.04 0.090 0.02"/>
      </geometry>
      <material name="LightGrey"/>
    </visual>
    <collision>
      <origin rpy="0 0 0" xyz="0 0 0"/>
      <geometry>
        <box size="0.04 0.090 0.02"/>
      </geometry>
    </collision>
  </link>
  <joint name="gripper_left_joint" type="fixed">
    <origin rpy="0 0 0" xyz="0 0.045 0"/>
    <parent link="arm_left_3_link"/>
    <child link="gripper_left_link"/>
  </joint>
  <transmission name="arm_left_1_trans">
    <type>transmission_interface/SimpleTransmission</type>
    <actuator name="arm_left_1_motor">
      <mechanicalReduction>1.0</mechanicalReduction>
    </actuator>
    <joint name="arm_left_1_joint">
      <!-- <hardwareInterface>hardware_interface/PositionJointInterface</hardwareInterface> -->
      <hardwareInterface>hardware_interface/EffortJointInterface</hardwareInterface>
    </joint>
  </transmission>
</robot>

