<?xml version="1.0" ?>
<!--
  Author: Poh Zhi-Ee (zhiee.poh@httechnology.com)
  Copyright (c) 2019, SIW Manufacturing Sdn. Bhd.
  All rights reserved.
-->
<robot name="lobot" xmlns:xacro="http://ros.org/wiki/xacro">

    <!--File includes-->
    <xacro:include filename="$(find lobot_description)/urdf/leg/leg.transmission.xacro" />

    <!--Constant parameters-->

    <xacro:property name="deg_to_rad" value="0.01745329251994329577" />

    <xacro:property name="leg_friction" value="1.0" />
    <xacro:property name="leg_damping" value="1.0" />
    <xacro:property name="leg_reduction" value="1.0" />
    <xacro:property name="leg_eps" value="0.0" />
    <xacro:property name="leg_version" value="0.0" />

    <xacro:property name="leg_1_joint_max_vel" value="4" />
    <xacro:property name="leg_2_joint_max_vel" value="${3.94 if leg_version=='v1' else 2.27}" />
    <xacro:property name="leg_3_joint_max_vel" value="${6.0  if leg_version=='v1' else 3.64}" />
    <xacro:property name="leg_4_joint_max_vel" value="${4.25 if leg_version=='v1' else 3.225}" />
    <xacro:property name="leg_5_joint_max_vel" value="${4.0  if leg_version=='v1' else 2.44}" />
    <xacro:property name="leg_6_joint_max_vel" value="${3.94 if leg_version=='v1' else 2.27}" />

    <xacro:property name="leg_1_joint_effort" value="${50.69 if leg_version=='v1' else 42.7}" />
    <xacro:property name="leg_2_joint_effort" value="${71.4  if leg_version=='v1' else 64.0}" />
    <xacro:property name="leg_3_joint_effort" value="${62.9  if leg_version=='v1' else 55.7}" />
    <xacro:property name="leg_4_joint_effort" value="${140.4 if leg_version=='v1' else 138.3}" />
    <xacro:property name="leg_5_joint_effort" value="${91.6  if leg_version=='v1' else 80.9}" />
    <xacro:property name="leg_6_joint_effort" value="${71.48 if leg_version=='v1' else 64.0}" />

    <xacro:macro name="lobot_leg" params="name parent side reflect">

        <link name="leg_${side}_1_link">
            <inertial>
                <mass value="0.02901" />
                <origin xyz="0 0 0" rpy="0.0 0.0 0.0" />
                <inertia ixx="0.00132187534" ixy="0.00000001514" ixz="0.00040022268" iyy="0.0018528617" iyz="0.00000050713" izz="0.00084231334" />
            </inertial>
            <visual>
                <origin rpy="0 ${90*deg_to_rad} 0" xyz="0 0 0" />
                <geometry>
                    <cylinder radius="0.01" length="0.02" />
                </geometry>
                <material name="LightGrey" />
            </visual>
            <collision>
                <origin rpy="0 ${90*deg_to_rad} 0" xyz="0 0 0" />
                <geometry>
                    <cylinder radius="0.01" length="0.02" />
                </geometry>
            </collision>
        </link>

        <joint name="leg_${side}_1_joint" type="revolute">
            <origin xyz="0  ${-reflect*0.0315} -0.0475" rpy="0 0 0" />
            <axis xyz="1 0 0" />
            <parent link="${parent}" />
            <child link="leg_${side}_1_link" />
            <limit lower="-1.57" upper="1.57" effort="50" velocity="4" />
        </joint>

        <link name="leg_${side}_2_link">
            <inertial>
                <mass value="0.069621" />
                <origin xyz="0 0 0" rpy="0.0 0.0 0.0" />
                <inertia ixx="0.0008416476" ixy="-0.00000268743" ixz="0.00000667199" iyy="0.00039794844" iyz="0.00002668971" izz="0.00084196694" />
            </inertial>
            <visual>
                    <origin rpy="0 ${26.565*deg_to_rad} 0" xyz="0.02 0 0" />
                <geometry>
                    <!-- <cylinder radius="0.01" length="0.02" /> -->
                    <box size="0.02 0.04 0.02" />
                </geometry>
                <material name="LightGrey" />
            </visual>
            <collision>
                <origin rpy="0 ${26.565*deg_to_rad} 0" xyz="0.02 0 0" />
                <geometry>
                    <!-- <cylinder radius="0.01" length="0.02" /> -->
                    <box size="0.03 0.03 0.02" />
                </geometry>
            </collision>
        </link>

        <joint name="leg_${side}_2_joint" type="revolute">
            <origin xyz="0 0 -0.04707" rpy="0 0 0" />
            <axis xyz="0 1 0" />
            <parent link="leg_${side}_1_link" />
            <child link="leg_${side}_2_link" />
            <limit lower="${-22.5*deg_to_rad - reflect*7.5*deg_to_rad}" upper="${22.5*deg_to_rad - reflect*7.5*deg_to_rad}" effort="${leg_2_joint_effort}" velocity="${leg_2_joint_max_vel}" />
        </joint>

        <link name="leg_${side}_3a_link">
            <inertial>
                <mass value="0.04" />
                <origin xyz="0 0 0" rpy="0.0 0.0 0.0" />
                <inertia ixx="0.0008416476" ixy="-0.00000268743" ixz="0.00000667199" iyy="0.00039794844" iyz="0.00002668971" izz="0.00084196694" />
            </inertial>
            <visual>
                <origin rpy="0 0 0" xyz="0 0 0.004" />
                <geometry>
                    <box size="0.02 0.04 0.025" />
                </geometry>
                <material name="LightGrey" />
            </visual>
            <collision>
                <origin rpy="0 0 0" xyz="0 0 0.004" />
                <geometry>
                    <box size="0.02 0.04 0.025" />
                </geometry>
            </collision>
        </link>

        <joint name="leg_${side}_3a_joint" type="fixed">
            <origin xyz="0.04104 0 -0.020" rpy="0 0 0" />
            <parent link="leg_${side}_2_link" />
            <child link="leg_${side}_3a_link" />
        </joint>

        <link name="leg_${side}_3_link">
            <inertial>
                <mass value="0.05" />
                <origin xyz="0 0 0" rpy="0.0 0.0 0.0" />
                <inertia ixx="0.0008416476" ixy="-0.00000268743" ixz="0.00000667199" iyy="0.00039794844" iyz="0.00002668971" izz="0.00084196694" />
            </inertial>
            <visual>
                <origin rpy="0 0 0" xyz="0 0 -0.02" />
                <geometry>
                    <box size="0.02 0.04 0.04" />
                </geometry>
                <material name="LightGrey" />
            </visual>
            <collision>
                <origin rpy="0 0 0" xyz="0 0 -0.02" />
                <geometry>
                    <box size="0.02 0.04 0.04" />
                </geometry>
            </collision>
        </link>

        <joint name="leg_${side}_3_joint" type="revolute">
            <origin xyz="0 0 -0.02477" rpy="0 0 0" />
            <axis xyz="0 1 0" />
            <parent link="leg_${side}_3a_link" />
            <child link="leg_${side}_3_link" />
            <!-- <dynamics friction="${leg_friction}" damping="${leg_damping}" /> -->
            <limit lower="${ -100.0 * deg_to_rad}" upper="${45 * deg_to_rad}" effort="${leg_3_joint_effort}" velocity="${leg_3_joint_max_vel}" />

            <!-- <safety_controller k_position="100" k_velocity="100" soft_lower_limit="${-100.0 * deg_to_rad + leg_eps}" soft_upper_limit="${  45.0 * deg_to_rad - leg_eps}" /> -->
        </joint>

        <link name="leg_${side}_4_link">
            <inertial>
                <mass value="0.06" />
                <origin xyz="0 0 0" rpy="0.0 0.0 0.0" />
                <inertia ixx="0.0008416476" ixy="-0.00000268743" ixz="0.00000667199" iyy="0.00039794844" iyz="0.00002668971" izz="0.00084196694" />
            </inertial>
            <visual>
                <origin rpy="${90*deg_to_rad} 0 0" xyz="0 0 0" />
                <geometry>
                    <cylinder radius="0.01" length="0.02" />
                </geometry>
                <material name="LightGrey" />
            </visual>
            <collision>
                <origin rpy="${90*deg_to_rad} 0 0" xyz="0 0 0" />
                <geometry>
                    <cylinder radius="0.01" length="0.02" />
                </geometry>
            </collision>
        </link>

        <joint name="leg_${side}_4_joint" type="revolute">
            <origin xyz="0 0 -0.05856" rpy="0 0 0" />
            <axis xyz="0 1 0" />
            <parent link="leg_${side}_3_link" />
            <child link="leg_${side}_4_link" />
            <dynamics friction="${leg_friction}" damping="${leg_damping}" />
            <limit lower="${ -100.0 * deg_to_rad}" upper="${45 * deg_to_rad}" effort="${leg_3_joint_effort}" velocity="${leg_3_joint_max_vel}" />

            <safety_controller k_position="100" k_velocity="100" soft_lower_limit="${-100.0 * deg_to_rad + leg_eps}" soft_upper_limit="${  45.0 * deg_to_rad - leg_eps}" />
        </joint>

        <link name="leg_${side}_5_link">
            <inertial>
                <mass value="0.05" />
                <origin xyz="0 0 0" rpy="0.0 0.0 0.0" />
                <inertia ixx="0.0008416476" ixy="-0.00000268743" ixz="0.00000667199" iyy="0.00039794844" iyz="0.00002668971" izz="0.00084196694" />
            </inertial>
            <visual>
                <origin rpy="0 0 0" xyz="0 0 -0.005" />
                <geometry>
                    <!-- <cylinder radius="0.01" length="0.02" /> -->
                    <box size="0.095 0.07 0.01" />
                </geometry>
                <material name="LightGrey" />
            </visual>
            <collision>
                <origin rpy="0 0 0" xyz="0 0 -0.005" />
                <geometry>
                    <box size="0.095 0.07 0.01" />
                </geometry>
            </collision>
        </link>

        <joint name="leg_${side}_5_joint" type="revolute">
            <origin xyz="0 0 -0.04707" rpy="0 0 0" />
            <axis xyz="1 0 0" />
            <parent link="leg_${side}_4_link" />
            <child link="leg_${side}_5_link" />
            <limit lower="${ -100.0 * deg_to_rad}" upper="${45 * deg_to_rad}" effort="${leg_3_joint_effort}" velocity="${leg_3_joint_max_vel}" />
        </joint>

        <gazebo reference="leg_${side}_1_link">
            <mu1>0.9</mu1>
            <mu2>0.9</mu2>
        </gazebo>

        <gazebo reference="leg_${side}_1_joint">
            <implicitSpringDamper>1</implicitSpringDamper>
        </gazebo>
        <gazebo reference="leg_${side}_2_joint">
            <implicitSpringDamper>1</implicitSpringDamper>
        </gazebo>
        <gazebo reference="leg_${side}_3_joint">
            <implicitSpringDamper>1</implicitSpringDamper>
        </gazebo>
        <gazebo reference="leg_${side}_4_joint">
            <implicitSpringDamper>1</implicitSpringDamper>
        </gazebo>
        <!--
        <gazebo reference="leg_${side}_5_joint">
            <implicitSpringDamper>1</implicitSpringDamper>
        </gazebo>
        <gazebo reference="leg_${side}_6_joint">
            <implicitSpringDamper>1</implicitSpringDamper>
            <provideFeedback>1</provideFeedback>
        </gazebo> -->

        <xacro:lobot_leg_transmission name="${name}" side="${side}" number="1" reduction="${leg_reduction}" />
        <xacro:lobot_leg_transmission name="${name}" side="${side}" number="2" reduction="${leg_reduction}" />
        <xacro:lobot_leg_transmission name="${name}" side="${side}" number="3" reduction="${leg_reduction}" />
        <xacro:lobot_leg_transmission name="${name}" side="${side}" number="4" reduction="${leg_reduction}" />
        <!-- 
        <xacro:lobot_leg_simple_transmission name="${name}" side="${side}" number="5" reduction="${leg_reduction}" />
        <xacro:lobot_leg_simple_transmission name="${name}" side="${side}" number="6" reduction="${leg_reduction}" />
        -->
    </xacro:macro>
</robot>