<?xml version="1.0"?>
<!--

  Copyright (c) 2011-2012, PAL Robotics, S.L.
  All rights reserved.

  This work is licensed under the Creative Commons Attribution-NonCommercial-NoDerivs 3.0 Unported License.
  To view a copy of this license, visit http://creativecommons.org/licenses/by-nc-nd/3.0/ or send a letter to
  Creative Commons, 444 Castro Street, Suite 900, Mountain View, California, 94041, USA.
-->
<robot name="lobot" 
    xmlns:xacro="http://ros.org/wiki/xacro">

    <!--File includes-->
    <xacro:include filename="$(find lobot_description)/urdf/leg/leg.transmission.xacro" />

    <!--Constant parameters-->

    <xacro:property name="deg_to_rad" value="0.01745329251994329577" />

    <xacro:property name="leg_friction" value="1.0" />
    <xacro:property name="leg_damping" value="1.0" />
    <xacro:property name="leg_reduction" value="1.0" />
    <xacro:property name="leg_eps" value="0.0" />
    <xacro:property name="leg_version" value="0.0" />

    <xacro:property name="leg_1_joint_max_vel" value="4" />
    <xacro:property name="leg_2_joint_max_vel" value="${3.94 if leg_version=='v1' else 2.27}" />
    <xacro:property name="leg_3_joint_max_vel" value="${6.0  if leg_version=='v1' else 3.64}" />
    <xacro:property name="leg_4_joint_max_vel" value="${4.25 if leg_version=='v1' else 3.225}" />
    <xacro:property name="leg_5_joint_max_vel" value="${4.0  if leg_version=='v1' else 2.44}" />
    <xacro:property name="leg_6_joint_max_vel" value="${3.94 if leg_version=='v1' else 2.27}" />

    <xacro:property name="leg_1_joint_effort" value="${50.69 if leg_version=='v1' else 42.7}" />
    <xacro:property name="leg_2_joint_effort" value="${71.4  if leg_version=='v1' else 64.0}" />
    <xacro:property name="leg_3_joint_effort" value="${62.9  if leg_version=='v1' else 55.7}" />
    <xacro:property name="leg_4_joint_effort" value="${140.4 if leg_version=='v1' else 138.3}" />
    <xacro:property name="leg_5_joint_effort" value="${91.6  if leg_version=='v1' else 80.9}" />
    <xacro:property name="leg_6_joint_effort" value="${71.48 if leg_version=='v1' else 64.0}" />

    <xacro:macro name="lobot_leg" params="name parent side reflect">

        <link name="leg_${side}_1_link">
            <inertial>
                <mass value="1.02901"/>
                <origin xyz="-0.02571 0 0.02557" rpy="0 0 0"/>
                <inertia ixx="0.00132187534" ixy="0.00000001514" ixz="0.00040022268" iyy="0.0018528617" iyz="0.00000050713" izz="0.00084231334"/>
            </inertial>
            <visual>
                <origin rpy="0 0 0" xyz="0 0 0"/>
                <geometry>
                    <box size="0.15 0.10 0.20"/>
                </geometry>
                <material name="LightGrey" />
            </visual>
            <collision>
                <origin xyz="0 0 0" rpy="0 0 0" />
                <geometry>
                    <box size="0.15 0.10 0.20"/>
                    <!-- <box size="0.3 0.35 0.14"/> -->
                </geometry>
            </collision>
        </link>

        <joint name="leg_${side}_1_joint" type="revolute">
            <origin xyz="0  ${-reflect*0.075} -0.14353" rpy="0 0 0"/>
            <axis xyz="0 0 1"/>
            <parent link="${parent}"/>
            <child link="leg_${side}_1_link"/>
            <limit lower="-1.57" upper="1.57" effort="50" velocity="4" />
            <dynamics friction="${leg_friction}" damping="${leg_damping}"/>
            <!-- <limit lower="${-37.5*deg_to_rad + reflect*7.5*deg_to_rad}" upper="${37.5*deg_to_rad + reflect*7.5*deg_to_rad}" effort="${leg_1_joint_effort}" velocity="${leg_1_joint_max_vel}" /> -->

            <!-- <safety_controller k_position="100" k_velocity="100" soft_lower_limit="${-75*deg_to_rad + reflect*7.5*deg_to_rad + leg_eps}" soft_upper_limit="${ 37.5*deg_to_rad + reflect*7.5*deg_to_rad - leg_eps}" /> -->
        </joint>

        <gazebo reference="leg_${side}_1_link">
            <mu1>0.9</mu1>
            <mu2>0.9</mu2>
        </gazebo>
        
        <!-- contact model for foot surface -->
        <!-- <gazebo reference="leg_${side}_6_link">
            <kp>1000000.0</kp>
            <kd>100.0</kd>
            <mu1>1.0</mu1>
            <mu2>1.0</mu2>
            <fdir1>0 0 1</fdir1>
            <maxVel>1.0</maxVel>
            <minDepth>0.00</minDepth>
            <implicitSpringDamper>1</implicitSpringDamper>
        </gazebo> -->

        <!--force torque sensor -->
        <!--xacro:reemc_force_torque_sensor name="leg_${side}_6_link" update_rate="100.0"/-->

        <gazebo reference="leg_${side}_1_joint">
            <implicitSpringDamper>1</implicitSpringDamper>
        </gazebo>
        <!-- <gazebo reference="leg_${side}_2_joint">
            <implicitSpringDamper>1</implicitSpringDamper>
        </gazebo>
        <gazebo reference="leg_${side}_3_joint">
            <implicitSpringDamper>1</implicitSpringDamper>
        </gazebo>
        <gazebo reference="leg_${side}_4_joint">
            <implicitSpringDamper>1</implicitSpringDamper>
        </gazebo>
        <gazebo reference="leg_${side}_5_joint">
            <implicitSpringDamper>1</implicitSpringDamper>
        </gazebo>
        <gazebo reference="leg_${side}_6_joint">
            <implicitSpringDamper>1</implicitSpringDamper>
            <provideFeedback>1</provideFeedback>
        </gazebo> -->

        <xacro:lobot_leg_transmission name="${name}" side="${side}" number="1" reduction="${leg_reduction}" />

        <!-- <xacro:reemc_leg_simple_transmission name="${name}" side="${side}" number="2" reduction="${leg_reduction}" />
        <xacro:reemc_leg_simple_transmission name="${name}" side="${side}" number="3" reduction="${leg_reduction}" />
        <xacro:reemc_leg_simple_transmission name="${name}" side="${side}" number="4" reduction="${leg_reduction}" />
        <xacro:reemc_leg_simple_transmission name="${name}" side="${side}" number="5" reduction="${leg_reduction}" />
        <xacro:reemc_leg_simple_transmission name="${name}" side="${side}" number="6" reduction="${leg_reduction}" /> -->
    </xacro:macro>
</robot>
